Workbook

Sheet Anleitung
A1: Finanzplan Padel-Halle Landshut — 4 Indoor-Courts in gemieteter Halle
A2: Planungsstand Juli 2026 — alle Beträge netto, sofern nicht anders vermerkt
A4: So benutzt du das Modell
A5: 1. | B5: Alle Eingaben stehen auf dem Blatt »Annahmen«. Nur dort ändern.
A6: 2. | B6: BLAUE Zahlen sind Eingaben und dürfen überschrieben werden.
A7: 3. | B7: SCHWARZE Zahlen sind Formeln. Nicht überschreiben — sonst rechnet das Modell falsch.
A8: 4. | B8: GRÜNE Zahlen sind Verweise auf ein anderes Blatt.
A9: 5. | B9: GELB hinterlegt = Schlüsselannahme mit großem Ergebnishebel.
A10: 6. | B10: Die vier Szenario-Regler auf »Annahmen« wirken auf das gesamte Modell.
A11: 7. | B11: Blatt »Sensitivität« rechnet Varianten für Jahr 3 durch, ohne die Regler zu verändern.
A13: Blätter
A14: Annahmen | B14: Alle Eingaben: Kapazität, Preise, Auslastung, Zusatzerlöse, Kosten, Szenario-Regler
A15: Investition | B15: Investitionsplan, Puffer, Liquiditätsreserve, Vorsteuer-Zwischenfinanzierung
A16: Finanzierung | B16: Mittelherkunft und Kapitaldienst je Darlehen über 5 Jahre
A17: Umsatz | B17: Verkaufte Stunden, Courterlöse, Zusatzerlöse, Gesamtauslastung
A18: Kosten | B18: Miete, Energie, Personal und übrige Betriebskosten
A19: GuV_Cashflow | B19: EBITDA, Abschreibung, Zinsen, Steuern, Cashflow nach Kapitaldienst
A20: Liquiditaet_J1 | B20: Monatliche Liquidität im ersten Betriebsjahr — verlangt die Bank
A21: Break_Even | B21: Break-even-Auslastung und Deckungsbeitragsrechnung
A22: Sensitivitaet | B22: Sieben Varianten für Jahr 3 im Vergleich
A24: Legende
A25: 123.456 € | B25: Eingabe — anpassbar
A26: 123.456 € | B26: Formel — nicht überschreiben
A27: 123.456 € | B27: Verweis auf anderes Blatt
A28: 123.456 € | B28: Schlüsselannahme
A30: Hinweise zur Belastbarkeit
A31: Alle Werte sind Planannahmen auf Basis von Branchen-Benchmarks (Stand Juli 2026), keine Zusagen.
A32: Vor der Finanzierungsentscheidung verbindlich einholen: Mietangebot mit Höhenaufmaß,
A33: drei schriftliche Court-Angebote, Bauvoranfrage beim Bauamt, Energiekostenangebot.
A34: Quellen der Benchmarks: Deutscher Padel Verband, padel-guide.de, rechn24.de, padel-konzept.de.

Sheet Annahmen
A1: Annahmen — alle blauen Zellen sind anpassbar
A3: 1. Kapazität
A4: Anzahl Courts | B4: 4 | G4: Layout 2 × 2, Erweiterung auf 5–6 möglich
A5: Öffnungsstunden pro Tag | B5: 16 | G5: 07:00–23:00 Uhr
A6: Betriebstage pro Jahr | B6: 361 | G6: abzüglich Feiertage/Wartung
A7: Vermarktungswochen pro Jahr | B7: 50 | G7: konservativer Abschlag für Ferien/Feiertage
A8: Prime-Stunden je Woche und Court | B8: 45 | G8: Mo–Fr 17–22, Sa/So 9–19
A9: Standard-Stunden je Woche und Court | B9: 46 | G9: Mo–Fr 9–17, So ab 19
A10: Rand-Stunden je Woche und Court | B10: 21 | G10: täglich 7–9 und 22–23
A11: Summe Stunden je Woche und Court | B11: =B8+B9+B10 -> 112 | G11: Kontrolle: sollte Öffnungsstunden × 7 entsprechen
A12: Buchbare Court-Stunden pro Jahr | B12: =B4*B5*B6 -> 23104 | G12: Kapazitätsbasis für die Auslastungsquote
A14: 2. Preise je Court und Stunde
A15: Umsatzsteuersatz | B15: 0.19 | G15: Kurzfristige Sportanlagenvermietung: 19 %
B17: brutto | C17: netto
A18: Prime | B18: 44 | C18: =B18/(1+$B$15) -> 36.97479 | G18: 11,00 € je Spieler — größter Ergebnishebel neben der Auslastung
A19: Standard | B19: 30 | C19: =B19/(1+$B$15) -> 25.210084
A20: Rand (früh/spät) | B20: 22 | C20: =B20/(1+$B$15) -> 18.487395
A22: 3. Auslastung je Zeitfenster
B23: Jahr 1 | C23: Jahr 2 | D23: Jahr 3 | E23: Jahr 4 | F23: Jahr 5
A24: Prime | B24: 0.65 | C24: 0.72 | D24: 0.78 | E24: 0.8 | F24: 0.81 | G24: Prime füllt sich von allein; Standard ist die eigentliche Vertriebsaufgabe
A25: Standard | B25: 0.25 | C25: 0.33 | D25: 0.4 | E25: 0.42 | F25: 0.43
A26: Rand (früh/spät) | B26: 0.15 | C26: 0.2 | D26: 0.25 | E26: 0.26 | F26: 0.27
A28: 4. Zusatzerlöse (netto, € pro Jahr)
B29: Jahr 1 | C29: Jahr 2 | D29: Jahr 3 | E29: Jahr 4 | F29: Jahr 5
A30: Getränke, Snacks, Automaten | B30: 30000 | C30: 38000 | D30: 45000 | E30: 48000 | F30: 50000
A31: Kurse, Training, Camps | B31: 14000 | C31: 20000 | D31: 25000 | E31: 27000 | F31: 28000
A32: Abos und Mitgliedschaften | B32: 10000 | C32: 18000 | D32: 24000 | E32: 25000 | F32: 26000
A33: Shop, Verleih, Bespannung | B33: 8000 | C33: 12000 | D33: 16000 | E33: 17000 | F33: 18000
A34: Turniere, Events, Sponsoring | B34: 13000 | C34: 12000 | D34: 12000 | E34: 13000 | F34: 14000
A35: Summe Zusatzerlöse | B35: =SUM(B30:B34) -> 75000 | C35: =SUM(C30:C34) -> 100000 | D35: =SUM(D30:D34) -> 122000 | E35: =SUM(E30:E34) -> 130000 | F35: =SUM(F30:F34) -> 136000
A37: 5. Kosten
A38: Hallenfläche (m²) | B38: 1500 | G38: 1.300–1.600 m² für 4 Courts inkl. Nebenräume
A39: Kaltmiete (€ je m² und Monat) | B39: 5.5 | G39: Zielkorridor 4,50–6,00 € — darüber kippt die Kalkulation
A40: Nebenkosten (€ je m² und Monat) | B40: 1.2 | G40: Kappungsgrenze im Mietvertrag verhandeln
A41: Mietfreie Monate im Betriebsjahr 1 | B41: 1 | G41: Der Großteil der mietfreien Zeit liegt in der Bauphase (Jahr 0)
A42: Mietsteigerung p. a. ab Jahr 3 | B42: 0.015 | G42: Staffelmiete statt Indexmiete verhandeln
B44: Jahr 1 | C44: Jahr 2 | D44: Jahr 3 | E44: Jahr 4 | F44: Jahr 5
A45: Energie (Strom, Wärme, Wasser) | B45: 45000 | C45: 47000 | D45: 48000 | E45: 49000 | F45: 50000
A46: Personal inkl. Geschäftsführung | B46: 92000 | C46: 112000 | D46: 126000 | E46: 132000 | F46: 136000 | G46: Personalquote ~25 % — nur mit Smart-Access-Betrieb erreichbar
A47: Instandhaltung, Reinigung, Courtpflege | B47: 12000 | C47: 14000 | D47: 16000 | E47: 17000 | F47: 18000
...

Sheet Investition
A1: Investitionsplan
A3: Positionen (netto)
A4: 4 Indoor-Padelcourts (Panorama), montiert | B4: 128000 | D4: Zielkorridor 26.000–30.000 € je Court — hier konservativ 32.000 €
A5: Bodenertüchtigung / Ausgleichsschicht ca. 1.000 m² | B5: 35000 | D5: entfällt teilweise bei ebenem Industrieboden
A6: LED-Sportbeleuchtung inkl. Steuerung | B6: 30000 | D6: ≥ 500 lux, je Court über die Buchung schaltbar
A7: Planung, Statik, Brandschutzkonzept, Gebühren | B7: 32000 | D7: Architekt 12–20 T€, Brandschutz 5–10 T€
A8: Baulicher Brandschutz | B8: 40000 | D8: größter Unsicherheitsposten — objektabhängig
A9: Umkleiden, Duschen, WC, Sanitärinstallation | B9: 70000 | D9: entfällt weitgehend bei vorhandenen Sozialräumen
A10: Empfang, Lounge, Theke, Möblierung | B10: 35000
A11: Heizung, Lüftung, Elektro-Hauptverteilung | B11: 40000 | D11: Anschlussleistung ≥ 60 kW
A12: Akustikmaßnahmen (Decken- und Wandabsorber) | B12: 15000 | D12: Padel ist laut — nicht optional
A13: IT: Smart Access, Buchung, Kasse, WLAN, Video | B13: 25000
A14: Erstausstattung Verleih, Bälle, Shop | B14: 12000
A15: Branding, Beschilderung, Website, Launch-Marketing | B15: 25000
A16: Bauleitung und Baunebenkosten | B16: 15000 | D16: örtlicher Bauleiter oder Architekt
A17: Zwischensumme | B17: =SUM(B4:B16) -> 502000
A18: Sicherheitspuffer | B18: 0.15 | D18: Branchenempfehlung 15–25 %
A19: Investition gesamt | B19: =B17*(1+B18) -> 577300
A21: Liquiditätsreserve für die Anlaufphase | B21: 80000 | D21: deckt Jahr 1 mit mind. 2 Monatsfixkosten Puffer
A22: Gesamtkapitalbedarf | B22: =B19+B21 -> 657300
A24: Abgeleitete Größen
A25: Aktivierungsfähige Investition | B25: =B19*Annahmen!B63 -> 502251
A26: Jahresabschreibung (linear) | B26: =B25/Annahmen!B62 -> 50225.1
A27: Vorsteuer auf die Investition | B27: =B19*Annahmen!B15 -> 109687 | D27: wird erstattet, muss aber 1–3 Monate vorfinanziert werden
A28: Empfohlener Kontokorrentrahmen | B28: =ROUND(B27*0.7,-3) -> 77000 | D28: 70 % der Vorsteuer als Zwischenfinanzierung

Sheet Finanzierung
A1: Finanzierung und Kapitaldienst
A3: Mittelherkunft
A4: Eigenkapital (bar) | B4: 100000
A5: Founding-Member-Vorverkauf | B5: 50000 | H5: 100 × 499 € Kundenvorkasse, zinsfrei
A6: KfW ERP-Gründerkredit StartGeld | B6: 125000 | H6: max. 125 T€, 80 % Haftungsfreistellung, über die Hausbank
A7: LfA Startkredit / GuW Bayern | B7: 252300 | H7: bis 15 Jahre Laufzeit und Zinsbindung, über die Hausbank
A8: Mietkauf Courts und Beleuchtung | B8: 130000 | H8: Courts dienen als Sicherheit
A9: Summe Mittelherkunft | B9: =SUM(B4:B8) -> 657300
A10: Gesamtkapitalbedarf | B10: =Investition!B22 -> 657300
A11: Deckungslücke (muss 0 sein) | B11: =B9-B10 -> 0
A12: Eigenkapitalquote inkl. Vorverkauf | B12: =(B4+B5)/B9 -> 0.2282063 | H12: Richtwert der Hausbanken: mindestens 20 %
A14: Darlehensparameter
B15: Betrag | C15: Zinssatz | D15: Laufzeit (J.) | E15: tilgungsfrei (J.)
A16: KfW ERP-Gründerkredit StartGeld | B16: =B6 -> 125000 | C16: 0.05 | D16: 10 | E16: 2 | H16: Tilgung linear ab dem ersten tilgungspflichtigen Jahr
A17: LfA Startkredit / GuW | B17: =B7 -> 252300 | C17: 0.045 | D17: 15 | E17: 3
A18: Mietkauf Courts | B18: =B8 -> 130000 | C18: 0.06 | D18: 7 | E18: 0
A20: Kapitaldienst je Darlehen
A21: KfW ERP-Gründerkredit StartGeld | B21: Jahr 1 | C21: Jahr 2 | D21: Jahr 3 | E21: Jahr 4 | F21: Jahr 5
A22: Restschuld Jahresanfang | B22: =B16 -> 125000 | C22: =B25 -> 125000 | D22: =C25 -> 125000 | E22: =D25 -> 109375 | F22: =E25 -> 93750
A23: Zinsen | B23: =B22*$C$16 -> 6250 | C23: =C22*$C$16 -> 6250 | D23: =D22*$C$16 -> 6250 | E23: =E22*$C$16 -> 5468.75 | F23: =F22*$C$16 -> 4687.5
A24: Tilgung | B24: =IF(1<=$E$16,0,MIN(B22,$B$16/($D$16-$E$16))) -> 0 | C24: =IF(2<=$E$16,0,MIN(C22,$B$16/($D$16-$E$16))) -> 0 | D24: =IF(3<=$E$16,0,MIN(D22,$B$16/($D$16-$E$16))) -> 15625 | E24: =IF(4<=$E$16,0,MIN(E22,$B$16/($D$16-$E$16))) -> 15625 | F24: =IF(5<=$E$16,0,MIN(F22,$B$16/($D$16-$E$16))) -> 15625
A25: Restschuld Jahresende | B25: =B22-B24 -> 125000 | C25: =C22-C24 -> 125000 | D25: =D22-D24 -> 109375 | E25: =E22-E24 -> 93750 | F25: =F22-F24 -> 78125
A27: LfA Startkredit / GuW | B27: Jahr 1 | C27: Jahr 2 | D27: Jahr 3 | E27: Jahr 4 | F27: Jahr 5
A28: Restschuld Jahresanfang | B28: =B17 -> 252300 | C28: =B31 -> 252300 | D28: =C31 -> 252300 | E28: =D31 -> 252300 | F28: =E31 -> 231275
A29: Zinsen | B29: =B28*$C$17 -> 11353.5 | C29: =C28*$C$17 -> 11353.5 | D29: =D28*$C$17 -> 11353.5 | E29: =E28*$C$17 -> 11353.5 | F29: =F28*$C$17 -> 10407.375
A30: Tilgung | B30: =IF(1<=$E$17,0,MIN(B28,$B$17/($D$17-$E$17))) -> 0 | C30: =IF(2<=$E$17,0,MIN(C28,$B$17/($D$17-$E$17))) -> 0 | D30: =IF(3<=$E$17,0,MIN(D28,$B$17/($D$17-$E$17))) -> 0 | E30: =IF(4<=$E$17,0,MIN(E28,$B$17/($D$17-$E$17))) -> 21025 | F30: =IF(5<=$E$17,0,MIN(F28,$B$17/($D$17-$E$17))) -> 21025
A31: Restschuld Jahresende | B31: =B28-B30 -> 252300 | C31: =C28-C30 -> 252300 | D31: =D28-D30 -> 252300 | E31: =E28-E30 -> 231275 | F31: =F28-F30 -> 210250
A33: Mietkauf Courts | B33: Jahr 1 | C33: Jahr 2 | D33: Jahr 3 | E33: Jahr 4 | F33: Jahr 5
A34: Restschuld Jahresanfang | B34: =B18 -> 130000 | C34: =B37 -> 111428.57 | D34: =C37 -> 92857.143 | E34: =D37 -> 74285.714 | F34: =E37 -> 55714.286
A35: Zinsen | B35: =B34*$C$18 -> 7800 | C35: =C34*$C$18 -> 6685.7143 | D35: =D34*$C$18 -> 5571.4286 | E35: =E34*$C$18 -> 4457.1429 | F35: =F34*$C$18 -> 3342.8571
A36: Tilgung | B36: =IF(1<=$E$18,0,MIN(B34,$B$18/($D$18-$E$18))) -> 18571.429 | C36: =IF(2<=$E$18,0,MIN(C34,$B$18/($D$18-$E$18))) -> 18571.429 | D36: =IF(3<=$E$18,0,MIN(D34,$B$18/($D$18-$E$18))) -> 18571.429 | E36: =IF(4<=$E$18,0,MIN(E34,$B$18/($D$18-$E$18))) -> 18571.429 | F36: =IF(5<=$E$18,0,MIN(F34,$B$18/($D$18-$E$18))) -> 18571.429
A37: Restschuld Jahresende | B37: =B34-B36 -> 111428.57 | C37: =C34-C36 -> 92857.143 | D37: =D34-D36 -> 74285.714 | E37: =E34-E36 -> 55714.286 | F37: =F34-F36 -> 37142.857
A39: Kapitaldienst gesamt
B40: Jahr 1 | C40: Jahr 2 | D40: Jahr 3 | E40: Jahr 4 | F40: Jahr 5
A41: Zinsaufwand | B41: =B23+B29+B35 -> 25403.5 | C41: =C23+C29+C35 -> 24289.214 | D41: =D23+D29+D35 -> 23174.929 | E41: =E23+E29+E35 -> 21279.393 | F41: =F23+F29+F35 -> 18437.732
A42: Tilgung | B42: =B24+B30+B36 -> 18571.429 | C42: =C24+C30+C36 -> 18571.429 | D42: =D24+D30+D36 -> 34196.429 | E42: =E24+E30+E36 -> 55221.429 | F42: =F24+F30+F36 -> 55221.429
A43: Kapitaldienst | B43: =B41+B42 -> 43974.929 | C43: =C41+C42 -> 42860.643 | D43: =D41+D42 -> 57371.357 | E43: =E41+E42 -> 76500.821 | F43: =F41+F42 -> 73659.161

Sheet Umsatz
A1: Umsatzplanung (netto)
A3: Verkaufte Court-Stunden
B4: Jahr 1 | C4: Jahr 2 | D4: Jahr 3 | E4: Jahr 4 | F4: Jahr 5
A5: Prime | B5: =Annahmen!$B$4*Annahmen!$B$7*Annahmen!$B$8*Annahmen!B24*Annahmen!$B$56 -> 5850 | C5: =Annahmen!$B$4*Annahmen!$B$7*Annahmen!$B$8*Annahmen!C24*Annahmen!$B$56 -> 6480 | D5: =Annahmen!$B$4*Annahmen!$B$7*Annahmen!$B$8*Annahmen!D24*Annahmen!$B$56 -> 7020 | E5: =Annahmen!$B$4*Annahmen!$B$7*Annahmen!$B$8*Annahmen!E24*Annahmen!$B$56 -> 7200 | F5: =Annahmen!$B$4*Annahmen!$B$7*Annahmen!$B$8*Annahmen!F24*Annahmen!$B$56 -> 7290
A6: Standard | B6: =Annahmen!$B$4*Annahmen!$B$7*Annahmen!$B$9*Annahmen!B25*Annahmen!$B$56 -> 2300 | C6: =Annahmen!$B$4*Annahmen!$B$7*Annahmen!$B$9*Annahmen!C25*Annahmen!$B$56 -> 3036 | D6: =Annahmen!$B$4*Annahmen!$B$7*Annahmen!$B$9*Annahmen!D25*Annahmen!$B$56 -> 3680 | E6: =Annahmen!$B$4*Annahmen!$B$7*Annahmen!$B$9*Annahmen!E25*Annahmen!$B$56 -> 3864 | F6: =Annahmen!$B$4*Annahmen!$B$7*Annahmen!$B$9*Annahmen!F25*Annahmen!$B$56 -> 3956
A7: Rand (früh/spät) | B7: =Annahmen!$B$4*Annahmen!$B$7*Annahmen!$B$10*Annahmen!B26*Annahmen!$B$56 -> 630 | C7: =Annahmen!$B$4*Annahmen!$B$7*Annahmen!$B$10*Annahmen!C26*Annahmen!$B$56 -> 840 | D7: =Annahmen!$B$4*Annahmen!$B$7*Annahmen!$B$10*Annahmen!D26*Annahmen!$B$56 -> 1050 | E7: =Annahmen!$B$4*Annahmen!$B$7*Annahmen!$B$10*Annahmen!E26*Annahmen!$B$56 -> 1092 | F7: =Annahmen!$B$4*Annahmen!$B$7*Annahmen!$B$10*Annahmen!F26*Annahmen!$B$56 -> 1134
A8: Verkaufte Stunden gesamt | B8: =B5+B6+B7 -> 8780 | C8: =C5+C6+C7 -> 10356 | D8: =D5+D6+D7 -> 11750 | E8: =E5+E6+E7 -> 12156 | F8: =F5+F6+F7 -> 12380
A9: Gesamtauslastung | B9: =B8/Annahmen!$B$12 -> 0.38002078 | C9: =C8/Annahmen!$B$12 -> 0.44823407 | D9: =D8/Annahmen!$B$12 -> 0.50856994 | E9: =E8/Annahmen!$B$12 -> 0.52614266 | F9: =F8/Annahmen!$B$12 -> 0.53583795
A10: davon Prime-Time-Auslastung | B10: =Annahmen!B24*Annahmen!$B$56 -> 0.65 | C10: =Annahmen!C24*Annahmen!$B$56 -> 0.72 | D10: =Annahmen!D24*Annahmen!$B$56 -> 0.78 | E10: =Annahmen!E24*Annahmen!$B$56 -> 0.8 | F10: =Annahmen!F24*Annahmen!$B$56 -> 0.81
A12: Courterlöse
B13: Jahr 1 | C13: Jahr 2 | D13: Jahr 3 | E13: Jahr 4 | F13: Jahr 5
A14: Prime | B14: =B5*Annahmen!$C$18*Annahmen!$B$57 -> 216302.52 | C14: =C5*Annahmen!$C$18*Annahmen!$B$57 -> 239596.64 | D14: =D5*Annahmen!$C$18*Annahmen!$B$57 -> 259563.03 | E14: =E5*Annahmen!$C$18*Annahmen!$B$57 -> 266218.49 | F14: =F5*Annahmen!$C$18*Annahmen!$B$57 -> 269546.22
A15: Standard | B15: =B6*Annahmen!$C$19*Annahmen!$B$57 -> 57983.193 | C15: =C6*Annahmen!$C$19*Annahmen!$B$57 -> 76537.815 | D15: =D6*Annahmen!$C$19*Annahmen!$B$57 -> 92773.109 | E15: =E6*Annahmen!$C$19*Annahmen!$B$57 -> 97411.765 | F15: =F6*Annahmen!$C$19*Annahmen!$B$57 -> 99731.092
A16: Rand (früh/spät) | B16: =B7*Annahmen!$C$20*Annahmen!$B$57 -> 11647.059 | C16: =C7*Annahmen!$C$20*Annahmen!$B$57 -> 15529.412 | D16: =D7*Annahmen!$C$20*Annahmen!$B$57 -> 19411.765 | E16: =E7*Annahmen!$C$20*Annahmen!$B$57 -> 20188.235 | F16: =F7*Annahmen!$C$20*Annahmen!$B$57 -> 20964.706
A17: Courterlöse gesamt | B17: =B14+B15+B16 -> 285932.77 | C17: =C14+C15+C16 -> 331663.87 | D17: =D14+D15+D16 -> 371747.9 | E17: =E14+E15+E16 -> 383818.49 | F17: =F14+F15+F16 -> 390242.02
A18: Mischerlös je Court-Stunde | B18: =IFERROR(B17/B8,0) -> 32.566375 | C18: =IFERROR(C17/C8,0) -> 32.026252 | D18: =IFERROR(D17/D8,0) -> 31.638119 | E18: =IFERROR(E17/E8,0) -> 31.574407 | F18: =IFERROR(F17/F8,0) -> 31.521972
A19: Courterlöse je Court | B19: =B17/Annahmen!$B$4 -> 71483.193 | C19: =C17/Annahmen!$B$4 -> 82915.966 | D19: =D17/Annahmen!$B$4 -> 92936.975 | E19: =E17/Annahmen!$B$4 -> 95954.622 | F19: =F17/Annahmen!$B$4 -> 97560.504
A21: Zusatzerlöse
B22: Jahr 1 | C22: Jahr 2 | D22: Jahr 3 | E22: Jahr 4 | F22: Jahr 5
A23: Getränke, Snacks, Automaten | B23: =Annahmen!B30*Annahmen!$B$56 -> 30000 | C23: =Annahmen!C30*Annahmen!$B$56 -> 38000 | D23: =Annahmen!D30*Annahmen!$B$56 -> 45000 | E23: =Annahmen!E30*Annahmen!$B$56 -> 48000 | F23: =Annahmen!F30*Annahmen!$B$56 -> 50000
A24: Kurse, Training, Camps | B24: =Annahmen!B31*Annahmen!$B$56 -> 14000 | C24: =Annahmen!C31*Annahmen!$B$56 -> 20000 | D24: =Annahmen!D31*Annahmen!$B$56 -> 25000 | E24: =Annahmen!E31*Annahmen!$B$56 -> 27000 | F24: =Annahmen!F31*Annahmen!$B$56 -> 28000
A25: Abos und Mitgliedschaften | B25: =Annahmen!B32*Annahmen!$B$56 -> 10000 | C25: =Annahmen!C32*Annahmen!$B$56 -> 18000 | D25: =Annahmen!D32*Annahmen!$B$56 -> 24000 | E25: =Annahmen!E32*Annahmen!$B$56 -> 25000 | F25: =Annahmen!F32*Annahmen!$B$56 -> 26000
A26: Shop, Verleih, Bespannung | B26: =Annahmen!B33*Annahmen!$B$56 -> 8000 | C26: =Annahmen!C33*Annahmen!$B$56 -> 12000 | D26: =Annahmen!D33*Annahmen!$B$56 -> 16000 | E26: =Annahmen!E33*Annahmen!$B$56 -> 17000 | F26: =Annahmen!F33*Annahmen!$B$56 -> 18000
A27: Turniere, Events, Sponsoring | B27: =Annahmen!B34*Annahmen!$B$56 -> 13000 | C27: =Annahmen!C34*Annahmen!$B$56 -> 12000 | D27: =Annahmen!D34*Annahmen!$B$56 -> 12000 | E27: =Annahmen!E34*Annahmen!$B$56 -> 13000 | F27: =Annahmen!F34*Annahmen!$B$56 -> 14000
A28: Zusatzerlöse gesamt | B28: =SUM(B23:B27) -> 75000 | C28: =SUM(C23:C27) -> 100000 | D28: =SUM(D23:D27) -> 122000 | E28: =SUM(E23:E27) -> 130000 | F28: =SUM(F23:F27) -> 136000
A30: UMSATZ GESAMT | B30: =B17+B28 -> 360932.77 | C30: =C17+C28 -> 431663.87 | D30: =D17+D28 -> 493747.9 | E30: =E17+E28 -> 513818.49 | F30: =F17+F28 -> 526242.02
A31: Zusatzerlösquote | B31: =B28/B30 -> 0.20779493 | C31: =C28/C30 -> 0.23166173 | D31: =D28/D30 -> 0.24708966 | E31: =E28/E30 -> 0.25300763 | F31: =F28/F30 -> 0.25843622 | G31: Ziel: 21 % in Jahr 1, 25 % ab Jahr 3

Sheet Kosten
A1: Kostenplanung (netto)
A3: Betriebskosten
B4: Jahr 1 | C4: Jahr 2 | D4: Jahr 3 | E4: Jahr 4 | F4: Jahr 5
A5: Miete inkl. Nebenkosten | B5: =Annahmen!$B$38*(Annahmen!$B$39+Annahmen!$B$59+Annahmen!$B$40)*12*(1+Annahmen!$B$42)^0-Annahmen!$B$38*(Annahmen!$B$39+Annahmen!$B$59)*Annahmen!$B$41 -> 112350 | C5: =Annahmen!$B$38*(Annahmen!$B$39+Annahmen!$B$59+Annahmen!$B$40)*12*(1+Annahmen!$B$42)^0 -> 120600 | D5: =Annahmen!$B$38*(Annahmen!$B$39+Annahmen!$B$59+Annahmen!$B$40)*12*(1+Annahmen!$B$42)^1 -> 122409 | E5: =Annahmen!$B$38*(Annahmen!$B$39+Annahmen!$B$59+Annahmen!$B$40)*12*(1+Annahmen!$B$42)^2 -> 124245.13 | F5: =Annahmen!$B$38*(Annahmen!$B$39+Annahmen!$B$59+Annahmen!$B$40)*12*(1+Annahmen!$B$42)^3 -> 126108.81 | G5: Fläche × (Kaltmiete + Aufschlag + NK) × 12, Steigerung ab Jahr 3
A6: Energie | B6: =Annahmen!B45*Annahmen!$B$58 -> 45000 | C6: =Annahmen!C45*Annahmen!$B$58 -> 47000 | D6: =Annahmen!D45*Annahmen!$B$58 -> 48000 | E6: =Annahmen!E45*Annahmen!$B$58 -> 49000 | F6: =Annahmen!F45*Annahmen!$B$58 -> 50000
A7: Personal inkl. Geschäftsführung | B7: =Annahmen!B46 -> 92000 | C7: =Annahmen!C46 -> 112000 | D7: =Annahmen!D46 -> 126000 | E7: =Annahmen!E46 -> 132000 | F7: =Annahmen!F46 -> 136000
A8: Instandhaltung, Reinigung, Courtpflege | B8: =Annahmen!B47 -> 12000 | C8: =Annahmen!C47 -> 14000 | D8: =Annahmen!D47 -> 16000 | E8: =Annahmen!E47 -> 17000 | F8: =Annahmen!F47 -> 18000
A9: IT, Buchungssystem, Zahlungsgebühren | B9: =Annahmen!B48 -> 13000 | C9: =Annahmen!C48 -> 15000 | D9: =Annahmen!D48 -> 17000 | E9: =Annahmen!E48 -> 18000 | F9: =Annahmen!F48 -> 18000
A10: Versicherungen | B10: =Annahmen!B49 -> 6000 | C10: =Annahmen!C49 -> 6000 | D10: =Annahmen!D49 -> 6000 | E10: =Annahmen!E49 -> 6000 | F10: =Annahmen!F49 -> 7000
A11: Marketing | B11: =Annahmen!B50 -> 20000 | C11: =Annahmen!C50 -> 15000 | D11: =Annahmen!D50 -> 14000 | E11: =Annahmen!E50 -> 14000 | F11: =Annahmen!F50 -> 14000
A12: Verwaltung, Steuerberatung, Recht | B12: =Annahmen!B51 -> 12000 | C12: =Annahmen!C51 -> 12000 | D12: =Annahmen!D51 -> 13000 | E12: =Annahmen!E51 -> 13000 | F12: =Annahmen!F51 -> 13000
A13: Verbrauchsmaterial | B13: =Annahmen!B52 -> 6000 | C13: =Annahmen!C52 -> 7000 | D13: =Annahmen!D52 -> 8000 | E13: =Annahmen!E52 -> 8000 | F13: =Annahmen!F52 -> 8000
A14: Wareneinsatz Getränke und Shop | B14: =(Umsatz!B23+Umsatz!B26)*Annahmen!$B$53 -> 19760 | C14: =(Umsatz!C23+Umsatz!C26)*Annahmen!$B$53 -> 26000 | D14: =(Umsatz!D23+Umsatz!D26)*Annahmen!$B$53 -> 31720 | E14: =(Umsatz!E23+Umsatz!E26)*Annahmen!$B$53 -> 33800 | F14: =(Umsatz!F23+Umsatz!F26)*Annahmen!$B$53 -> 35360
A15: BETRIEBSKOSTEN GESAMT | B15: =SUM(B5:B14) -> 338110 | C15: =SUM(C5:C14) -> 374600 | D15: =SUM(D5:D14) -> 402129 | E15: =SUM(E5:E14) -> 415045.14 | F15: =SUM(F5:F14) -> 425468.81
A17: davon fixe Kosten (ohne Wareneinsatz) | B17: =B15-B14 -> 318350 | C17: =C15-C14 -> 348600 | D17: =D15-D14 -> 370409 | E17: =E15-E14 -> 381245.14 | F17: =F15-F14 -> 390108.81
A18: Personalquote am Umsatz | B18: =Annahmen!B46/Umsatz!B30 -> 0.25489511 | C18: =Annahmen!C46/Umsatz!C30 -> 0.25946114 | D18: =Annahmen!D46/Umsatz!D30 -> 0.25519096 | E18: =Annahmen!E46/Umsatz!E30 -> 0.25690006 | F18: =Annahmen!F46/Umsatz!F30 -> 0.25843622
A19: Mietquote am Umsatz | B19: =B5/Umsatz!B30 -> 0.3112768 | C19: =C5/Umsatz!C30 -> 0.27938405 | D19: =D5/Umsatz!D30 -> 0.24791802 | E19: =E5/Umsatz!E30 -> 0.24180744 | F19: =F5/Umsatz!F30 -> 0.23964033

Sheet GuV_Cashflow
A1: Ergebnis- und Liquiditätsrechnung
A3: Gewinn- und Verlustrechnung
B4: Jahr 1 | C4: Jahr 2 | D4: Jahr 3 | E4: Jahr 4 | F4: Jahr 5
A5: Umsatz | B5: =Umsatz!B30 -> 360932.77 | C5: =Umsatz!C30 -> 431663.87 | D5: =Umsatz!D30 -> 493747.9 | E5: =Umsatz!E30 -> 513818.49 | F5: =Umsatz!F30 -> 526242.02
A6: abzüglich Betriebskosten | B6: =-Kosten!B15 -> -338110 | C6: =-Kosten!C15 -> -374600 | D6: =-Kosten!D15 -> -402129 | E6: =-Kosten!E15 -> -415045.14 | F6: =-Kosten!F15 -> -425468.81
A7: EBITDA | B7: =B5+B6 -> 22822.773 | C7: =C5+C6 -> 57063.866 | D7: =D5+D6 -> 91618.899 | E7: =E5+E6 -> 98773.352 | F7: =F5+F6 -> 100773.2
A8: EBITDA-Marge | B8: =IFERROR(B7/B5,0) -> 0.063232754 | C8: =IFERROR(C7/C5,0) -> 0.13219514 | D8: =IFERROR(D7/D5,0) -> 0.18555805 | E8: =IFERROR(E7/E5,0) -> 0.19223394 | F8: =IFERROR(F7/F5,0) -> 0.19149593
A9: abzüglich Abschreibung | B9: =-Investition!$B$26 -> -50225.1 | C9: =-Investition!$B$26 -> -50225.1 | D9: =-Investition!$B$26 -> -50225.1 | E9: =-Investition!$B$26 -> -50225.1 | F9: =-Investition!$B$26 -> -50225.1
A10: abzüglich Zinsaufwand | B10: =-Finanzierung!B41 -> -25403.5 | C10: =-Finanzierung!C41 -> -24289.214 | D10: =-Finanzierung!D41 -> -23174.929 | E10: =-Finanzierung!E41 -> -21279.393 | F10: =-Finanzierung!F41 -> -18437.732
A11: Ergebnis vor Steuern | B11: =B7+B9+B10 -> -52805.827 | C11: =C7+C9+C10 -> -17450.449 | D11: =D7+D9+D10 -> 18218.871 | E11: =E7+E9+E10 -> 27268.86 | F11: =F7+F9+F10 -> 32110.373
A12: Verlustvortrag Jahresanfang | B12: 0 | C12: =B14 -> 52805.827 | D12: =C14 -> 70256.276 | E12: =D14 -> 52037.405 | F12: =E14 -> 24768.546
A13: Ertragsteuern | B13: =-MAX(0,B11-B12)*Annahmen!$B$64 -> 0 | C13: =-MAX(0,C11-C12)*Annahmen!$B$64 -> 0 | D13: =-MAX(0,D11-D12)*Annahmen!$B$64 -> 0 | E13: =-MAX(0,E11-E12)*Annahmen!$B$64 -> 0 | F13: =-MAX(0,F11-F12)*Annahmen!$B$64 -> -2202.5481
A14: Verlustvortrag Jahresende | B14: =MAX(0,B12-B11) -> 52805.827 | C14: =MAX(0,C12-C11) -> 70256.276 | D14: =MAX(0,D12-D11) -> 52037.405 | E14: =MAX(0,E12-E11) -> 24768.546 | F14: =MAX(0,F12-F11) -> 0
A15: Jahresüberschuss | B15: =B11+B13 -> -52805.827 | C15: =C11+C13 -> -17450.449 | D15: =D11+D13 -> 18218.871 | E15: =E11+E13 -> 27268.86 | F15: =F11+F13 -> 29907.824
A17: Cashflow
B18: Jahr 1 | C18: Jahr 2 | D18: Jahr 3 | E18: Jahr 4 | F18: Jahr 5
A19: EBITDA | B19: =B7 -> 22822.773 | C19: =C7 -> 57063.866 | D19: =D7 -> 91618.899 | E19: =E7 -> 98773.352 | F19: =F7 -> 100773.2
A20: abzüglich Kapitaldienst (Zins + Tilgung) | B20: =-Finanzierung!B43 -> -43974.929 | C20: =-Finanzierung!C43 -> -42860.643 | D20: =-Finanzierung!D43 -> -57371.357 | E20: =-Finanzierung!E43 -> -76500.821 | F20: =-Finanzierung!F43 -> -73659.161
A21: abzüglich Ertragsteuern | B21: =B13 -> 0 | C21: =C13 -> 0 | D21: =D13 -> 0 | E21: =E13 -> 0 | F21: =F13 -> -2202.5481
A22: Cashflow nach Kapitaldienst | B22: =B19+B20+B21 -> -21152.155 | C22: =C19+C20+C21 -> 14203.223 | D22: =D19+D20+D21 -> 34247.542 | E22: =E19+E20+E21 -> 22272.531 | F22: =F19+F20+F21 -> 24911.496
A23: kumulierter Cashflow | B23: =B22 -> -21152.155 | C23: =B23+C22 -> -6948.9328 | D23: =C23+D22 -> 27298.609 | E23: =D23+E22 -> 49571.14 | F23: =E23+F22 -> 74482.636
A24: Liquidität Jahresende | B24: =Investition!$B$21+B22 -> 58847.845 | C24: =B24+C22 -> 73051.067 | D24: =C24+D22 -> 107298.61 | E24: =D24+E22 -> 129571.14 | F24: =E24+F22 -> 154482.64 | G24: Warnschwelle: unter 2 Monatsfixkosten
A25: Liquidität in Monaten Fixkosten | B25: =IFERROR(B24/(Kosten!B17/12),0) -> 2.2182319 | C25: =IFERROR(C24/(Kosten!C17/12),0) -> 2.5146667 | D25: =IFERROR(D24/(Kosten!D17/12),0) -> 3.4761124 | E25: =IFERROR(E24/(Kosten!E17/12),0) -> 4.0783568 | F25: =IFERROR(F24/(Kosten!F17/12),0) -> 4.7519861

Sheet Liquiditaet_J1
A1: Monatliche Liquidität im ersten Betriebsjahr
A2: Die Bank verlangt diese Aufstellung. Saisonfaktoren müssen in Summe 100 % ergeben.
B4: Jan | C4: Feb | D4: Mär | E4: Apr | F4: Mai | G4: Jun | H4: Jul | I4: Aug | J4: Sep | K4: Okt | L4: Nov | M4: Dez | N4: Summe
A5: Saisonfaktor Umsatz | B5: 0.1 | C5: 0.095 | D5: 0.095 | E5: 0.08 | F5: 0.07 | G5: 0.06 | H5: 0.05 | I5: 0.05 | J5: 0.08 | K5: 0.1 | L5: 0.11 | M5: 0.11 | N5: =SUM(B5:M5) -> 1
A6: Padel ist ein Wintersport-Substitut — Nov–Mär trägt den Umsatz
A7: Einzahlungen aus Umsatz | B7: =GuV_Cashflow!$B$5*B5 -> 36093.277 | C7: =GuV_Cashflow!$B$5*C5 -> 34288.613 | D7: =GuV_Cashflow!$B$5*D5 -> 34288.613 | E7: =GuV_Cashflow!$B$5*E5 -> 28874.622 | F7: =GuV_Cashflow!$B$5*F5 -> 25265.294 | G7: =GuV_Cashflow!$B$5*G5 -> 21655.966 | H7: =GuV_Cashflow!$B$5*H5 -> 18046.639 | I7: =GuV_Cashflow!$B$5*I5 -> 18046.639 | ... M7: =GuV_Cashflow!$B$5*M5 -> 39702.605 | N7: =SUM(B7:M7) -> 360932.77
A8: Fixe Betriebskosten | B8: =-Kosten!$B$17/12 -> -26529.167 | C8: =-Kosten!$B$17/12 -> -26529.167 | D8: =-Kosten!$B$17/12 -> -26529.167 | E8: =-Kosten!$B$17/12 -> -26529.167 | F8: =-Kosten!$B$17/12 -> -26529.167 | G8: =-Kosten!$B$17/12 -> -26529.167 | H8: =-Kosten!$B$17/12 -> -26529.167 | I8: =-Kosten!$B$17/12 -> -26529.167 | ... M8: =-Kosten!$B$17/12 -> -26529.167 | N8: =SUM(B8:M8) -> -318350
A9: Wareneinsatz (umsatzabhängig) | B9: =-Kosten!$B$14*B5 -> -1976 | C9: =-Kosten!$B$14*C5 -> -1877.2 | D9: =-Kosten!$B$14*D5 -> -1877.2 | E9: =-Kosten!$B$14*E5 -> -1580.8 | F9: =-Kosten!$B$14*F5 -> -1383.2 | G9: =-Kosten!$B$14*G5 -> -1185.6 | H9: =-Kosten!$B$14*H5 -> -988 | I9: =-Kosten!$B$14*I5 -> -988 | ... M9: =-Kosten!$B$14*M5 -> -2173.6 | N9: =SUM(B9:M9) -> -19760
A10: Kapitaldienst | B10: =-Finanzierung!$B$43/12 -> -3664.5774 | C10: =-Finanzierung!$B$43/12 -> -3664.5774 | D10: =-Finanzierung!$B$43/12 -> -3664.5774 | E10: =-Finanzierung!$B$43/12 -> -3664.5774 | F10: =-Finanzierung!$B$43/12 -> -3664.5774 | G10: =-Finanzierung!$B$43/12 -> -3664.5774 | H10: =-Finanzierung!$B$43/12 -> -3664.5774 | I10: =-Finanzierung!$B$43/12 -> -3664.5774 | ... M10: =-Finanzierung!$B$43/12 -> -3664.5774 | N10: =SUM(B10:M10) -> -43974.929
A11: Monatssaldo | B11: =SUM(B7:B10) -> 3923.5333 | C11: =SUM(C7:C10) -> 2217.6694 | D11: =SUM(D7:D10) -> 2217.6694 | E11: =SUM(E7:E10) -> -2899.9222 | F11: =SUM(F7:F10) -> -6311.6499 | G11: =SUM(G7:G10) -> -9723.3777 | H11: =SUM(H7:H10) -> -13135.105 | I11: =SUM(I7:I10) -> -13135.105 | ... M11: =SUM(M7:M10) -> 7335.261 | N11: =SUM(B11:M11) -> -21152.155
A12: Liquidität Monatsende | B12: =Investition!$B$21+B11 -> 83923.533 | C12: =B12+C11 -> 86141.203 | D12: =C12+D11 -> 88358.872 | E12: =D12+E11 -> 85458.95 | F12: =E12+F11 -> 79147.3 | G12: =F12+G11 -> 69423.922 | H12: =G12+H11 -> 56288.817 | I12: =H12+I11 -> 43153.711 | J12: =I12+J11 -> 40253.789 | ... M12: =L12+M11 -> 58847.845
A14: Tiefster Liquiditätsstand im Jahr | B14: =MIN(B12:M12) -> 40253.789
A15: Wird dieser Wert negativ, reicht die Liquiditätsreserve nicht — Reserve auf
A16: Blatt »Investition« erhöhen oder Kontokorrentrahmen aufstocken.

Sheet Break_Even
A1: Break-even-Analyse (Basis Jahr 3)
A3: Rechnung
A4: Fixe Betriebskosten (ohne Wareneinsatz) | B4: =Kosten!D17 -> 370409
A5: zuzüglich Kapitaldienst | B5: =Finanzierung!D43 -> 57371.357
A6: zu deckender Fixblock | B6: =B4+B5 -> 427780.36
A7: abzüglich Deckungsbeitrag aus Zusatzerlösen | B7: =-(Umsatz!D28-Kosten!D14) -> -90280
A8: notwendiger Courterlös | B8: =B6+B7 -> 337500.36
A9: Mischerlös je Court-Stunde | B9: =Umsatz!D18 -> 31.638119
A10: notwendige Court-Stunden | B10: =IFERROR(B8/B9,0) -> 10667.523
A11: buchbare Court-Stunden pro Jahr | B11: =Annahmen!B12 -> 23104
A12: BREAK-EVEN-AUSLASTUNG | B12: =IFERROR(B10/B11,0) -> 0.46171757
A13: Plan-Auslastung Jahr 3 | B13: =Umsatz!D9 -> 0.50856994
A14: Sicherheitsabstand | B14: =B13-B12 -> 0.046852371 | D14: Ist dieser Wert negativ, trägt sich der Betrieb im Plan nicht.
A16: Einordnung
A17: Der Ergebnishebel liegt fast vollständig bei der Auslastung, nicht bei den Kosten.
A18: Zehn Prozent mehr oder weniger Auslastung bewegen das EBITDA um rund 45 T€ —
A19: mehr als jede denkbare Kosteneinsparung. Unter etwa 40 % Gesamtauslastung
A20: trägt sich der Betrieb nicht; die Off-Peak-Vermarktung ist deshalb existenziell.

Sheet Sensitivitaet
A1: Sensitivität — Varianten für Jahr 3
A2: Rechnet unabhängig von den Szenario-Reglern. Blaue Zellen sind die Hebel je Variante.
A4: Variante | B4: Auslastung | C4: Energie | D4: Mietaufschlag | E4: Umsatz | F4: Betriebskosten | G4: EBITDA | H4: EBITDA-Marge | I4: CF n. Kapitaldienst
A5: Basis | B5: 1 | C5: 1 | D5: 0 | E5: =Annahmen!$B$4*Annahmen!$B$7*(Annahmen!$B$8*Annahmen!$D$24*Annahmen!$C$18+Annahmen!$B$9*Annahmen!$D$25*Annahmen!$C$19+Annahmen!$B$10*Annahmen!$D$26*Annahmen!$C$20)*Annahmen!$B$57*$B5+Annahmen!$D$35*$B5 -> 493747.9 | F5: =Annahmen!$B$38*(Annahmen!$B$39+$D5+Annahmen!$B$40)*12*(1+Annahmen!$B$42)^1+Annahmen!$D$45*$C5+Annahmen!$D$46+Annahmen!$D$47+Annahmen!$D$48+Annahmen!$D$49+Annahmen!$D$50+Annahmen!$D$51+Annahmen!$D$52+(Annahmen!$D$30+Annahmen!$D$33)*$B5*Annahmen!$B$53 -> 402129 | G5: =E5-F5 -> 91618.899 | H5: =IFERROR(G5/E5,0) -> 0.18555805 | I5: =G5-Finanzierung!$D$43 -> 34247.542
A6: Auslastung −10 % | B6: 0.9 | C6: 1 | D6: 0 | E6: =Annahmen!$B$4*Annahmen!$B$7*(Annahmen!$B$8*Annahmen!$D$24*Annahmen!$C$18+Annahmen!$B$9*Annahmen!$D$25*Annahmen!$C$19+Annahmen!$B$10*Annahmen!$D$26*Annahmen!$C$20)*Annahmen!$B$57*$B6+Annahmen!$D$35*$B6 -> 444373.11 | F6: =Annahmen!$B$38*(Annahmen!$B$39+$D6+Annahmen!$B$40)*12*(1+Annahmen!$B$42)^1+Annahmen!$D$45*$C6+Annahmen!$D$46+Annahmen!$D$47+Annahmen!$D$48+Annahmen!$D$49+Annahmen!$D$50+Annahmen!$D$51+Annahmen!$D$52+(Annahmen!$D$30+Annahmen!$D$33)*$B6*Annahmen!$B$53 -> 398957 | G6: =E6-F6 -> 45416.109 | H6: =IFERROR(G6/E6,0) -> 0.10220265 | I6: =G6-Finanzierung!$D$43 -> -11955.248
A7: Auslastung +10 % | B7: 1.1 | C7: 1 | D7: 0 | E7: =Annahmen!$B$4*Annahmen!$B$7*(Annahmen!$B$8*Annahmen!$D$24*Annahmen!$C$18+Annahmen!$B$9*Annahmen!$D$25*Annahmen!$C$19+Annahmen!$B$10*Annahmen!$D$26*Annahmen!$C$20)*Annahmen!$B$57*$B7+Annahmen!$D$35*$B7 -> 543122.69 | F7: =Annahmen!$B$38*(Annahmen!$B$39+$D7+Annahmen!$B$40)*12*(1+Annahmen!$B$42)^1+Annahmen!$D$45*$C7+Annahmen!$D$46+Annahmen!$D$47+Annahmen!$D$48+Annahmen!$D$49+Annahmen!$D$50+Annahmen!$D$51+Annahmen!$D$52+(Annahmen!$D$30+Annahmen!$D$33)*$B7*Annahmen!$B$53 -> 405301 | G7: =E7-F7 -> 137821.69 | H7: =IFERROR(G7/E7,0) -> 0.25375793 | I7: =G7-Finanzierung!$D$43 -> 80450.332
A8: Energie +30 % | B8: 1 | C8: 1.3 | D8: 0 | E8: =Annahmen!$B$4*Annahmen!$B$7*(Annahmen!$B$8*Annahmen!$D$24*Annahmen!$C$18+Annahmen!$B$9*Annahmen!$D$25*Annahmen!$C$19+Annahmen!$B$10*Annahmen!$D$26*Annahmen!$C$20)*Annahmen!$B$57*$B8+Annahmen!$D$35*$B8 -> 493747.9 | F8: =Annahmen!$B$38*(Annahmen!$B$39+$D8+Annahmen!$B$40)*12*(1+Annahmen!$B$42)^1+Annahmen!$D$45*$C8+Annahmen!$D$46+Annahmen!$D$47+Annahmen!$D$48+Annahmen!$D$49+Annahmen!$D$50+Annahmen!$D$51+Annahmen!$D$52+(Annahmen!$D$30+Annahmen!$D$33)*$B8*Annahmen!$B$53 -> 416529 | G8: =E8-F8 -> 77218.899 | H8: =IFERROR(G8/E8,0) -> 0.15639337 | I8: =G8-Finanzierung!$D$43 -> 19847.542
A9: Kaltmiete +1,00 €/m² | B9: 1 | C9: 1 | D9: 1 | E9: =Annahmen!$B$4*Annahmen!$B$7*(Annahmen!$B$8*Annahmen!$D$24*Annahmen!$C$18+Annahmen!$B$9*Annahmen!$D$25*Annahmen!$C$19+Annahmen!$B$10*Annahmen!$D$26*Annahmen!$C$20)*Annahmen!$B$57*$B9+Annahmen!$D$35*$B9 -> 493747.9 | F9: =Annahmen!$B$38*(Annahmen!$B$39+$D9+Annahmen!$B$40)*12*(1+Annahmen!$B$42)^1+Annahmen!$D$45*$C9+Annahmen!$D$46+Annahmen!$D$47+Annahmen!$D$48+Annahmen!$D$49+Annahmen!$D$50+Annahmen!$D$51+Annahmen!$D$52+(Annahmen!$D$30+Annahmen!$D$33)*$B9*Annahmen!$B$53 -> 420399 | G9: =E9-F9 -> 73348.899 | H9: =IFERROR(G9/E9,0) -> 0.14855536 | I9: =G9-Finanzierung!$D$43 -> 15977.542
A10: Kaltmiete +1,50 €/m² | B10: 1 | C10: 1 | D10: 1.5 | E10: =Annahmen!$B$4*Annahmen!$B$7*(Annahmen!$B$8*Annahmen!$D$24*Annahmen!$C$18+Annahmen!$B$9*Annahmen!$D$25*Annahmen!$C$19+Annahmen!$B$10*Annahmen!$D$26*Annahmen!$C$20)*Annahmen!$B$57*$B10+Annahmen!$D$35*$B10 -> 493747.9 | F10: =Annahmen!$B$38*(Annahmen!$B$39+$D10+Annahmen!$B$40)*12*(1+Annahmen!$B$42)^1+Annahmen!$D$45*$C10+Annahmen!$D$46+Annahmen!$D$47+Annahmen!$D$48+Annahmen!$D$49+Annahmen!$D$50+Annahmen!$D$51+Annahmen!$D$52+(Annahmen!$D$30+Annahmen!$D$33)*$B10*Annahmen!$B$53 -> 429534 | G10: =E10-F10 -> 64213.899 | H10: =IFERROR(G10/E10,0) -> 0.13005402 | I10: =G10-Finanzierung!$D$43 -> 6842.542
A11: Worst Case kombiniert | B11: 0.9 | C11: 1.3 | D11: 1 | E11: =Annahmen!$B$4*Annahmen!$B$7*(Annahmen!$B$8*Annahmen!$D$24*Annahmen!$C$18+Annahmen!$B$9*Annahmen!$D$25*Annahmen!$C$19+Annahmen!$B$10*Annahmen!$D$26*Annahmen!$C$20)*Annahmen!$B$57*$B11+Annahmen!$D$35*$B11 -> 444373.11 | F11: =Annahmen!$B$38*(Annahmen!$B$39+$D11+Annahmen!$B$40)*12*(1+Annahmen!$B$42)^1+Annahmen!$D$45*$C11+Annahmen!$D$46+Annahmen!$D$47+Annahmen!$D$48+Annahmen!$D$49+Annahmen!$D$50+Annahmen!$D$51+Annahmen!$D$52+(Annahmen!$D$30+Annahmen!$D$33)*$B11*Annahmen!$B$53 -> 431627 | G11: =E11-F11 -> 12746.109 | H11: =IFERROR(G11/E11,0) -> 0.02868335 | I11: =G11-Finanzierung!$D$43 -> -44625.248
A13: Lesart
A14: Die Basisvariante muss dem EBITDA in Jahr 3 auf dem Blatt »GuV_Cashflow« entsprechen,
A15: solange die Szenario-Regler auf 100 % / 0 € stehen. Weicht sie ab, sind die Regler verändert.
A16: Ein negativer Cashflow in einer Variante bedeutet: Liquiditätsreserve wird angegriffen.
